File: Simulation/Transverse Ising model/0066.dc.dat
[Header]
TITLE,MPMS DC Measurement
BYAPP,MPMS Measurement,2.1,Summary
FILEOPENTIME, 1521632929.324000 3/21/2018, 12:48:49 PM

INFO, APPNAME, MPMS MultiVu Application, Revision 1.61,  Build 082

INFO, NAME, GrowthLiquid
INFO, WEIGHT, 1.000
INFO, AREA, 1.000
INFO, LENGTH, 1.000
INFO, SHAPE, ice
INFO, COMMENT,
INFO, SEQUENCE FILE: tempscan.seq


INFO, BACKGROUND DATA FILE:, None


STARTUPAXIS,X,4,LINEAR,AUTO,0.000000,0.000000
STARTUPAXIS,Y1,5,LINEAR,AUTO,0.000000,0.000000


STARTUPGROUP,Longitudinal
FIELDGROUP,Longitudinal,1,2,3,4,5,6,7,8,9,15,16,17,18,27,28
FIELDGROUP,Transverse,1,2,3,4,10,11,12,13,14,19,20,21,22,27,28

PLOT_APPEARANCE,ALL,HORZ_GRID_ON,VERT_GRID_ON,MARKERS_AND_LINES

[Data]
Time,Comment,Field (Oe),Temperature (K),Long Moment (emu),Long Scan Std Dev,Long Algorithm,Long Reg Fit,Long Percent Error (%),Trans Moment (emu),Trans Scan Std Dev,Trans Algorithm,Trans Reg Fit,Trans Percent Error (%),Long Moment [w/o ABS] (emu),Long Scan Std Dev [w/o ABS],Long Reg Fit [w/o ABS],Long Percent Error [w/o ABS] (%),Trans Moment [w/o ABS] (emu),Trans Scan Std Dev [w/o ABS],Trans Reg Fit [w/o ABS],Trans Percent Error [w/o ABS] (%),Points per Scan,Scans per Measurement,Scan Length (cm),Delta Temp (K),Rot Position (deg),Error,EC Comp. Running,Using ABS,
1521632929.322,,1.000000e+002,2.999919e+002,2.330805e-004,0.000000e+000,3,9.915768e-001,0.000000e+000,,,,,,,,,,,,,,24,1,6.000000e+000,1.480103e-002,0.000000e+000,0,,0,
1521633099.230,,1.000000e+002,2.941009e+002,2.382689e-004,0.000000e+000,3,9.897618e-001,0.000000e+000,,,,,,,,,,,,,,24,1,6.000000e+000,2.841187e-002,0.000000e+000,0,,0,
1521633253.173,,1.000000e+002,2.891433e+002,2.439582e-004,0.000000e+000,3,9.911858e-001,0.000000e+000,,,,,,,,,,,,,,24,1,6.000000e+000,1.358032e-002,0.000000e+000,0,,0,
1521633404.302,,1.000000e+002,2.841365e+002,2.479217e-004,0.000000e+000,3,9.911557e-001,0.000000e+000,,,,,,,,,,,,,,24,1,6.000000e+000,2.627563e-002,0.000000e+000,0,,0,
1521633555.151,,1.000000e+002,2.791780e+002,2.536384e-004,0.000000e+000,3,9.905907e-001,0.000000e+000,,,,,,,,,,,,,,24,1,6.000000e+000,0.000000e+000,0.000000e+000,0,,0,
1521633707.763,,1.000000e+002,2.742239e+002,2.584232e-004,0.000000e+000,3,9.903349e-001,0.000000e+000,,,,,,,,,,,,,,24,1,6.000000e+000,1.220703e-002,0.000000e+000,0,,0,
1521633857.537,,1.000000e+002,2.691727e+002,2.625384e-004,0.000000e+000,3,9.865457e-001,0.000000e+000,,,,,,,,,,,,,,24,1,6.000000e+000,4.690552e-002,0.000000e+000,0,,0,
1521634008.063,,1.000000e+002,2.641764e+002,2.688637e-004,0.000000e+000,3,9.889600e-001,0.000000e+000,,,,,,,,,,,,,,24,1,6.000000e+000,4.501343e-002,0.000000e+000,0,,0,
1521634157.299,,1.000000e+002,2.591438e+002,2.753267e-004,0.000000e+000,3,9.893404e-001,0.000000e+000,,,,,,,,,,,,,,24,1,6.000000e+000,7.580566e-002,0.000000e+000,0,,0,
1521634305.862,,1.000000e+002,2.541521e+002,2.799353e-004,0.000000e+000,3,9.897735e-001,0.000000e+000,,,,,,,,,,,,,,24,1,6.000000e+000,1.040039e-001,0.000000e+000,0,,0,
1521634454.831,,1.000000e+002,2.491598e+002,2.855705e-004,0.000000e+000,3,9.900281e-001,0.000000e+000,,,,,,,,,,,,,,24,1,6.000000e+000,1.100006e-001,0.000000e+000,0,,0,
1521634602.542,,1.000000e+002,2.441830e+002,2.910382e-004,0.000000e+000,3,9.900333e-001,0.000000e+000,,,,,,,,,,,,,,24,1,6.000000e+000,2.880859e-002,0.000000e+000,0,,0,
1521634750.625,,1.000000e+002,2.391855e+002,2.954828e-004,0.000000e+000,3,9.886886e-001,0.000000e+000,,,,,,,,,,,,,,24,1,6.000000e+000,9.210205e-002,0.000000e+000,0,,0,
1521634897.974,,1.000000e+002,2.342170e+002,3.038590e-004,0.000000e+000,3,9.906002e-001,0.000000e+000,,,,,,,,,,,,,,24,1,6.000000e+000,5.299377e-002,0.000000e+000,0,,0,
1521635047.780,,1.000000e+002,2.291965e+002,3.107614e-004,0.000000e+000,3,9.908383e-001,0.000000e+000,,,,,,,,,,,,,,24,1,6.000000e+000,1.268005e-001,0.000000e+000,0,,0,
1521635195.732,,1.000000e+002,2.241553e+002,3.169558e-004,0.000000e+000,3,9.899151e-001,0.000000e+000,,,,,,,,,,,,,,24,1,6.000000e+000,1.132050e-001,0.000000e+000,0,,0,
1521635342.925,,1.000000e+002,2.192169e+002,3.234904e-004,0.000000e+000,3,9.899083e-001,0.000000e+000,,,,,,,,,,,,,,24,1,6.000000e+000,1.550293e-002,0.000000e+000,0,,0,
1521635489.287,,1.000000e+002,2.142269e+002,3.335846e-004,0.000000e+000,3,9.915464e-001,0.000000e+000,,,,,,,,,,,,,,24,1,6.000000e+000,7.400513e-003,0.000000e+000,0,,0,
1521635634.412,,1.000000e+002,2.092379e+002,3.394801e-004,0.000000e+000,3,9.905728e-001,0.000000e+000,,,,,,,,,,,,,,24,1,6.000000e+000,4.229736e-002,0.000000e+000,0,,0,
1521635782.710,,1.000000e+002,2.042737e+002,3.478928e-004,0.000000e+000,3,9.912736e-001,0.000000e+000,,,,,,,,,,,,,,24,1,6.000000e+000,3.370667e-002,0.000000e+000,0,,0,
1521635928.824,,1.000000e+002,1.992226e+002,3.564008e-004,0.000000e+000,3,9.911842e-001,0.000000e+000,,,,,,,,,,,,,,24,1,6.000000e+000,9.620667e-002,0.000000e+000,0,,0,
1521636073.105,,1.000000e+002,1.943095e+002,3.663614e-004,0.000000e+000,3,9.918375e-001,0.000000e+000,,,,,,,,,,,,,,24,1,6.000000e+000,4.890442e-002,0.000000e+000,0,,0,
1521636218.045,,1.000000e+002,1.892853e+002,3.743036e-004,0.000000e+000,3,9.911123e-001,0.000000e+000,,,,,,,,,,,,,,24,1,6.000000e+000,2.900696e-002,0.000000e+000,0,,0,
1521636363.761,,1.000000e+002,1.842142e+002,3.851455e-004,0.000000e+000,3,9.916360e-001,0.000000e+000,,,,,,,,,,,,,,24,1,6.000000e+000,1.923981e-001,0.000000e+000,0,,0,
1521636508.373,,1.000000e+002,1.793336e+002,3.950896e-004,0.000000e+000,3,9.916269e-001,0.000000e+000,,,,,,,,,,,,,,24,1,6.000000e+000,1.201019e-001,0.000000e+000,0,,0,
1521636652.707,,1.000000e+002,1.743535e+002,4.061142e-004,0.000000e+000,3,9.913724e-001,0.000000e+000,,,,,,,,,,,,,,24,1,6.000000e+000,2.470398e-002,0.000000e+000,0,,0,
1521636798.690,,1.000000e+002,1.693484e+002,4.182682e-004,0.000000e+000,3,9.908853e-001,0.000000e+000,,,,,,,,,,,,,,24,1,6.000000e+000,1.496887e-001,0.000000e+000,0,,0,
1521636931.041,,1.000000e+002,1.645584e+002,4.302589e-004,0.000000e+000,3,9.915804e-001,0.000000e+000,,,,,,,,,,,,,,24,1,6.000000e+000,6.639099e-002,0.000000e+000,0,,0,
1521637076.845,,1.000000e+002,1.593832e+002,4.439628e-004,0.000000e+000,3,9.912072e-001,0.000000e+000,,,,,,,,,,,,,,24,1,6.000000e+000,1.249695e-002,0.000000e+000,0,,0,
1521637220.020,,1.000000e+002,1.544319e+002,4.577369e-004,0.000000e+000,3,9.910263e-001,0.000000e+000,,,,,,,,,,,,,,24,1,6.000000e+000,2.236023e-001,0.000000e+000,0,,0,
1521637363.778,,1.000000e+002,1.494335e+002,4.726023e-004,0.000000e+000,3,9.920275e-001,0.000000e+000,,,,,,,,,,,,,,24,1,6.000000e+000,2.026062e-001,0.000000e+000,0,,0,
1521637508.348,,1.000000e+002,1.445250e+002,4.879267e-004,0.000000e+000,3,9.915553e-001,0.000000e+000,,,,,,,,,,,,,,24,1,6.000000e+000,1.865997e-001,0.000000e+000,0,,0,
1521637660.154,,1.000000e+002,1.394382e+002,5.037453e-004,0.000000e+000,3,9.922136e-001,0.000000e+000,,,,,,,,,,,,,,24,1,6.000000e+000,2.259827e-002,0.000000e+000,0,,0,
1521637792.430,,1.000000e+002,1.349363e+002,5.232196e-004,0.000000e+000,3,9.909388e-001,0.000000e+000,,,,,,,,,,,,,,24,1,6.000000e+000,1.887970e-001,0.000000e+000,0,,0,
1521637939.524,,1.000000e+002,1.295930e+002,5.444860e-004,0.000000e+000,3,9.916575e-001,0.000000e+000,,,,,,,,,,,,,,24,1,6.000000e+000,1.443024e-001,0.000000e+000,0,,0,
1521638083.290,,1.000000e+002,1.246263e+002,5.644602e-004,0.000000e+000,3,9.915501e-001,0.000000e+000,,,,,,,,,,,,,,24,1,6.000000e+000,1.476059e-001,0.000000e+000,0,,0,
1521638225.410,,1.000000e+002,1.198145e+002,5.835937e-004,0.000000e+000,3,9.675301e-001,0.000000e+000,,,,,,,,,,,,,,24,1,6.000000e+000,2.354965e-001,0.000000e+000,0,,0,
1521638371.190,,1.000000e+002,1.147265e+002,6.119346e-004,0.000000e+000,3,9.925036e-001,0.000000e+000,,,,,,,,,,,,,,24,1,6.000000e+000,1.882019e-001,0.000000e+000,0,,0,
1521638517.635,,1.000000e+002,1.096236e+002,6.406337e-004,0.000000e+000,3,9.929104e-001,0.000000e+000,,,,,,,,,,,,,,24,1,6.000000e+000,7.929993e-002,0.000000e+000,0,,0,
1521638659.254,,1.000000e+002,1.047363e+002,6.674671e-004,0.000000e+000,3,9.912851e-001,0.000000e+000,,,,,,,,,,,,,,24,1,6.000000e+000,1.940994e-001,0.000000e+000,0,,0,
1521638801.882,,1.000000e+002,9.981895e+001,6.995539e-004,0.000000e+000,3,9.912343e-001,0.000000e+000,,,,,,,,,,,,,,24,1,6.000000e+000,1.286240e-001,0.000000e+000,0,,0,
1521638943.897,,1.000000e+002,9.480042e+001,7.327586e-004,0.000000e+000,3,9.914988e-001,0.000000e+000,,,,,,,,,,,,,,24,1,6.000000e+000,1.314621e-001,0.000000e+000,0,,0,
1521639087.906,,1.000000e+002,8.981141e+001,7.718249e-004,0.000000e+000,3,9.916143e-001,0.000000e+000,,,,,,,,,,,,,,24,1,6.000000e+000,1.306763e-001,0.000000e+000,0,,0,
1521639231.415,,1.000000e+002,8.485625e+001,8.129870e-004,0.000000e+000,3,9.919559e-001,0.000000e+000,,,,,,,,,,,,,,24,1,6.000000e+000,1.884155e-001,0.000000e+000,0,,0,
1521639375.800,,1.000000e+002,7.987119e+001,8.590620e-004,0.000000e+000,3,9.919255e-001,0.000000e+000,,,,,,,,,,,,,,24,1,6.000000e+000,1.100922e-001,0.000000e+000,0,,0,
1521639519.872,,1.000000e+002,7.487460e+001,9.111101e-004,0.000000e+000,3,9.919709e-001,0.000000e+000,,,,,,,,,,,,,,24,1,6.000000e+000,8.118439e-002,0.000000e+000,0,,0,
1521639663.097,,1.000000e+002,6.981835e+001,9.691425e-004,0.000000e+000,3,9.918290e-001,0.000000e+000,,,,,,,,,,,,,,24,1,6.000000e+000,7.145691e-002,0.000000e+000,0,,0,
1521639806.807,,1.000000e+002,6.482485e+001,1.036742e-003,0.000000e+000,3,9.924161e-001,0.000000e+000,,,,,,,,,,,,,,24,1,6.000000e+000,3.521729e-002,0.000000e+000,0,,0,
1521639950.218,,1.000000e+002,5.980736e+001,1.111410e-003,0.000000e+000,3,9.925244e-001,0.000000e+000,,,,,,,,,,,,,,24,1,6.000000e+000,9.677887e-003,0.000000e+000,0,,0,
1521640091.502,,1.000000e+002,5.484503e+001,1.197527e-003,0.000000e+000,3,9.920749e-001,0.000000e+000,,,,,,,,,,,,,,24,1,6.000000e+000,8.281708e-003,0.000000e+000,0,,0,
1521640247.954,,1.000000e+002,4.996741e+001,1.290832e-003,0.000000e+000,3,9.911418e-001,0.000000e+000,,,,,,,,,,,,,,24,1,6.000000e+000,3.192139e-002,0.000000e+000,0,,0,
1521640386.947,,1.000000e+002,4.495133e+001,1.422709e-003,0.000000e+000,3,9.917685e-001,0.000000e+000,,,,,,,,,,,,,,24,1,6.000000e+000,2.059937e-003,0.000000e+000,0,,0,
1521640521.074,,1.000000e+002,3.997876e+001,1.567734e-003,0.000000e+000,3,9.914670e-001,0.000000e+000,,,,,,,,,,,,,,24,1,6.000000e+000,1.670837e-003,0.000000e+000,0,,0,
1521640650.279,,1.000000e+002,3.499812e+001,1.755885e-003,0.000000e+000,3,9.921780e-001,0.000000e+000,,,,,,,,,,,,,,24,1,6.000000e+000,0.000000e+000,0.000000e+000,0,,0,
1521640774.944,,1.000000e+002,2.996891e+001,1.997616e-003,0.000000e+000,3,9.917632e-001,0.000000e+000,,,,,,,,,,,,,,24,1,6.000000e+000,9.803772e-004,0.000000e+000,0,,0,
1521640895.388,,1.000000e+002,2.510304e+001,2.307913e-003,0.000000e+000,3,9.919819e-001,0.000000e+000,,,,,,,,,,,,,,24,1,6.000000e+000,1.449585e-003,0.000000e+000,0,,0,
1521641033.566,,1.000000e+002,2.000084e+001,2.772871e-003,0.000000e+000,3,9.914492e-001,0.000000e+000,,,,,,,,,,,,,,24,1,6.000000e+000,3.320694e-003,0.000000e+000,0,,0,
1521641152.534,,1.000000e+002,1.500628e+001,3.470147e-003,0.000000e+000,3,9.916914e-001,0.000000e+000,,,,,,,,,,,,,,24,1,6.000000e+000,4.389763e-003,0.000000e+000,0,,0,
1521641269.653,,1.000000e+002,9.602594e+000,4.721075e-003,0.000000e+000,3,9.924860e-001,0.000000e+000,,,,,,,,,,,,,,24,1,6.000000e+000,0.000000e+000,0.000000e+000,0,,0,
1521641400.197,,1.000000e+002,4.993214e+000,7.879390e-003,0.000000e+000,3,9.919316e-001,0.000000e+000,,,,,,,,,,,,,,24,1,6.000000e+000,2.583981e-003,0.000000e+000,0,,0,